Workbook

Sheet Seguimiento
A1: 🎓 SEGUIMIENTO DE CARRERA — INGENIERÍA QUÍMICA
A2: Plan 2023 • UTN — Facultad Regional Resistencia
A4: ✅ APROBADAS | C4: 📈 AVANCE | E4: ❌ NO CURSADAS / CURSANDO | G4: 📊 PROM. SIN APLAZOS | I4: 📚 HS. ELECT. APROBADAS
A5: =COUNTIF(F12:F64,"Aprobada") -> 0 | C5: =IFERROR(COUNTIF(F12:F52,"Aprobada")/41,0) -> 0 | E5: =COUNTIF(F12:F52,"No Cursada")+COUNTIF(F12:F52,"Cursando") -> 41 | G5: =IFERROR(AVERAGEIF(G12:G64,">="&6),"—") -> — | I5: {=SUMPRODUCT((F53:F65="Aprobada")*J53:J65)} -> 0
A6: 🟢 DISPONIBLES PARA CURSAR | E6: 📋 REGULARES | G6: 📉 PROM. CON APLAZOS | I6: 📊 % ELECT. COMPLETADAS
A7: =COUNTIF(H12:H52,"✅ Disponible") -> 9 | E7: =COUNTIF(F12:F64,"Regular") -> 0 | G7: {=IFERROR((SUMPRODUCT(IF(ISNUMBER(G12:G64),G12:G64,0))+SUMPRODUCT((ISNUMBER(Finales!G5:G57))*(Finales!G5:G57<6)*Finales!G5:G57)+SUMPRODUCT((ISNUMBER(Finales!I5:I57))*(Finales!I5:I57<6)*Finales!I5:I57)+SUMPRODUCT((ISNUMBER(Finales!K5:K57))*(Finales!K5:K57<6)*Finales!K5:K57)+SUMPRODUCT((ISNUMBER(Finales!M5:M57))*(Finales!M5:M57<6)*Finales!M5:M57)+SUMPRODUCT((ISNUMBER(Finales!O5:O57))*(Finales!O5:O57<6)*Finales!O5:O57)+SUMPRODUCT((ISNUMBER(Finales!Q5:Q57))*(Finales!Q5:Q57<6)*Finales!Q5:Q57))/(SUMPRODUCT(ISNUMBER(G12:G64)*1)+SUMPRODUCT((ISNUMBER(Finales!G5:G57))*(Finales!G5:G57<6))+SUMPRODUCT((ISNUMBER(Finales!I5:I57))*(Finales!I5:I57<6))+SUMPRODUCT((ISNUMBER(Finales!K5:K57))*(Finales!K5:K57<6))+SUMPRODUCT((ISNUMBER(Finales!M5:M57))*(Finales!M5:M57<6))+SUMPRODUCT((ISNUMBER(Finales!O5:O57))*(Finales!O5:O57<6))+SUMPRODUCT((ISNUMBER(Finales!Q5:Q57))*(Finales!Q5:Q57<6))),"—")} -> — | I7: {=IFERROR(SUMPRODUCT((F53:F65="Aprobada")*J53:J65)/24,0)} -> 0
A8: 💡 Columna "ESTADO" (F): seleccione del menú desplegable • Columna "NOTA FINAL" (G): ingrese la nota del examen final (1-10)
A11: N° | B11: NIVEL | C11: ASIGNATURA | D11: CURSADAS REQ. | E11: APROBADAS REQ. | F11: ESTADO | G11: NOTA FINAL | H11: DISPONIBLE | I11: MATERIAS FALTANTES PARA HABILITAR | J11: CARGA HORARIA
A12: 1 | B12: I | C12: Introducción a la Ingeniería Química | D12: - | E12: - | F12: No Cursada | G12: =IF(Finales!E5="","",Finales!E5) | H12: =IF(F12="Aprobada","✅ Aprobada",IF(F12="Regular","🔄 Regular",IF(F12="Cursando","📖 Cursando","✅ Disponible"))) -> ✅ Disponible | I12: =IF(F12="No Cursada","Sin correlativas","-") -> Sin correlativas | J12: 3
A13: 2 | B13: I | C13: Ingeniería y Sociedad | D13: - | E13: - | F13: No Cursada | G13: =IF(Finales!E6="","",Finales!E6) | H13: =IF(F13="Aprobada","✅ Aprobada",IF(F13="Regular","🔄 Regular",IF(F13="Cursando","📖 Cursando","✅ Disponible"))) -> ✅ Disponible | I13: =IF(F13="No Cursada","Sin correlativas","-") -> Sin correlativas | J13: 2
A14: 3 | B14: I | C14: Álgebra y Geometría Analítica | D14: - | E14: - | F14: No Cursada | G14: =IF(Finales!E7="","",Finales!E7) | H14: =IF(F14="Aprobada","✅ Aprobada",IF(F14="Regular","🔄 Regular",IF(F14="Cursando","📖 Cursando","✅ Disponible"))) -> ✅ Disponible | I14: =IF(F14="No Cursada","Sin correlativas","-") -> Sin correlativas | J14: 5
A15: 4 | B15: I | C15: Análisis Matemático I | D15: - | E15: - | F15: No Cursada | G15: =IF(Finales!E8="","",Finales!E8) | H15: =IF(F15="Aprobada","✅ Aprobada",IF(F15="Regular","🔄 Regular",IF(F15="Cursando","📖 Cursando","✅ Disponible"))) -> ✅ Disponible | I15: =IF(F15="No Cursada","Sin correlativas","-") -> Sin correlativas | J15: 5
A16: 5 | B16: I | C16: Física I | D16: - | E16: - | F16: No Cursada | G16: =IF(Finales!E9="","",Finales!E9) | H16: =IF(F16="Aprobada","✅ Aprobada",IF(F16="Regular","🔄 Regular",IF(F16="Cursando","📖 Cursando","✅ Disponible"))) -> ✅ Disponible | I16: =IF(F16="No Cursada","Sin correlativas","-") -> Sin correlativas | J16: 5
A17: 6 | B17: I | C17: Química | D17: - | E17: - | F17: No Cursada | G17: =IF(Finales!E10="","",Finales!E10) | H17: =IF(F17="Aprobada","✅ Aprobada",IF(F17="Regular","🔄 Regular",IF(F17="Cursando","📖 Cursando","✅ Disponible"))) -> ✅ Disponible | I17: =IF(F17="No Cursada","Sin correlativas","-") -> Sin correlativas | J17: 5
A18: 7 | B18: I | C18: Sistemas de Representación | D18: - | E18: - | F18: No Cursada | G18: =IF(Finales!E11="","",Finales!E11) | H18: =IF(F18="Aprobada","✅ Aprobada",IF(F18="Regular","🔄 Regular",IF(F18="Cursando","📖 Cursando","✅ Disponible"))) -> ✅ Disponible | I18: =IF(F18="No Cursada","Sin correlativas","-") -> Sin correlativas | J18: 2
A19: 8 | B19: I | C19: Fundamentos de Informática | D19: - | E19: - | F19: No Cursada | G19: =IF(Finales!E12="","",Finales!E12) | H19: =IF(F19="Aprobada","✅ Aprobada",IF(F19="Regular","🔄 Regular",IF(F19="Cursando","📖 Cursando","✅ Disponible"))) -> ✅ Disponible | I19: =IF(F19="No Cursada","Sin correlativas","-") -> Sin correlativas | J19: 2
A20: 9 | B20: II | C20: Introducción a Equipos y Procesos | D20: 1, 6 | E20: - | F20: No Cursada | G20: =IF(Finales!E13="","",Finales!E13) | H20: =IF(F20="Aprobada","✅ Aprobada",IF(F20="Regular","🔄 Regular",IF(F20="Cursando","📖 Cursando",IF(AND(OR(Datos!A2="Regular",Datos!A2="Aprobada"),OR(Datos!A7="Regular",Datos!A7="Aprobada")),"✅ Disponible","❌ No Disponible")))) -> ❌ No Disponible | I20: =IF(OR(F20="Aprobada",F20="Regular"),"-",IF(H20="✅ Disponible","Sin faltantes",IF(AND(Datos!A2<>"Regular",Datos!A2<>"Aprobada"),A12&"-"&C12&" (cursar); ","")&IF(AND(Datos!A7<>"Regular",Datos!A7<>"Aprobada"),A17&"-"&C17&" (cursar); ",""))) -> 1-Introducción a la Ingeniería Química (cursar); 6-Química (cursar); | J20: 3
A21: 10 | B21: II | C21: Probabilidad y Estadística | D21: 3, 4 | E21: - | F21: No Cursada | G21: =IF(Finales!E14="","",Finales!E14) | H21: =IF(F21="Aprobada","✅ Aprobada",IF(F21="Regular","🔄 Regular",IF(F21="Cursando","📖 Cursando",IF(AND(OR(Datos!A4="Regular",Datos!A4="Aprobada"),OR(Datos!A5="Regular",Datos!A5="Aprobada")),"✅ Disponible","❌ No Disponible")))) -> ❌ No Disponible | I21: =IF(OR(F21="Aprobada",F21="Regular"),"-",IF(H21="✅ Disponible","Sin faltantes",IF(AND(Datos!A4<>"Regular",Datos!A4<>"Aprobada"),A14&"-"&C14&" (cursar); ","")&IF(AND(Datos!A5<>"Regular",Datos!A5<>"Aprobada"),A15&"-"&C15&" (cursar); ",""))) -> 3-Álgebra y Geometría Analítica (cursar); 4-Análisis Matemático I (cursar); | J21: 3
A22: 11 | B22: II | C22: Química Inorgánica | D22: 6 | E22: - | F22: No Cursada | G22: =IF(Finales!E15="","",Finales!E15) | H22: =IF(F22="Aprobada","✅ Aprobada",IF(F22="Regular","🔄 Regular",IF(F22="Cursando","📖 Cursando",IF(AND(OR(Datos!A7="Regular",Datos!A7="Aprobada")),"✅ Disponible","❌ No Disponible")))) -> ❌ No Disponible | I22: =IF(OR(F22="Aprobada",F22="Regular"),"-",IF(H22="✅ Disponible","Sin faltantes",IF(AND(Datos!A7<>"Regular",Datos!A7<>"Aprobada"),A17&"-"&C17&" (cursar); ",""))) -> 6-Química (cursar); | J22: 4
A23: 12 | B23: II | C23: Análisis Matemático II | D23: 3, 4 | E23: - | F23: No Cursada | G23: =IF(Finales!E16="","",Finales!E16) | H23: =IF(F23="Aprobada","✅ Aprobada",IF(F23="Regular","🔄 Regular",IF(F23="Cursando","📖 Cursando",IF(AND(OR(Datos!A4="Regular",Datos!A4="Aprobada"),OR(Datos!A5="Regular",Datos!A5="Aprobada")),"✅ Disponible","❌ No Disponible")))) -> ❌ No Disponible | I23: =IF(OR(F23="Aprobada",F23="Regular"),"-",IF(H23="✅ Disponible","Sin faltantes",IF(AND(Datos!A4<>"Regular",Datos!A4<>"Aprobada"),A14&"-"&C14&" (cursar); ","")&IF(AND(Datos!A5<>"Regular",Datos!A5<>"Aprobada"),A15&"-"&C15&" (cursar); ",""))) -> 3-Álgebra y Geometría Analítica (cursar); 4-Análisis Matemático I (cursar); | J23: 5
A24: 13 | B24: II | C24: Física II | D24: 4, 5 | E24: - | F24: No Cursada | G24: =IF(Finales!E17="","",Finales!E17) | H24: =IF(F24="Aprobada","✅ Aprobada",IF(F24="Regular","🔄 Regular",IF(F24="Cursando","📖 Cursando",IF(AND(OR(Datos!A5="Regular",Datos!A5="Aprobada"),OR(Datos!A6="Regular",Datos!A6="Aprobada")),"✅ Disponible","❌ No Disponible")))) -> ❌ No Disponible | I24: =IF(OR(F24="Aprobada",F24="Regular"),"-",IF(H24="✅ Disponible","Sin faltantes",IF(AND(Datos!A5<>"Regular",Datos!A5<>"Aprobada"),A15&"-"&C15&" (cursar); ","")&IF(AND(Datos!A6<>"Regular",Datos!A6<>"Aprobada"),A16&"-"&C16&" (cursar); ",""))) -> 4-Análisis Matemático I (cursar); 5-Física I (cursar); | J24: 5
A25: 14 | B25: II | C25: Química Orgánica | D25: 6 | E25: - | F25: No Cursada | G25: =IF(Finales!E18="","",Finales!E18) | H25: =IF(F25="Aprobada","✅ Aprobada",IF(F25="Regular","🔄 Regular",IF(F25="Cursando","📖 Cursando",IF(AND(OR(Datos!A7="Regular",Datos!A7="Aprobada")),"✅ Disponible","❌ No Disponible")))) -> ❌ No Disponible | I25: =IF(OR(F25="Aprobada",F25="Regular"),"-",IF(H25="✅ Disponible","Sin faltantes",IF(AND(Datos!A7<>"Regular",Datos!A7<>"Aprobada"),A17&"-"&C17&" (cursar); ",""))) -> 6-Química (cursar); | J25: 5
A26: 15 | B26: II | C26: Legislación | D26: 1, 2 | E26: - | F26: No Cursada | G26: =IF(Finales!E19="","",Finales!E19) | H26: =IF(F26="Aprobada","✅ Aprobada",IF(F26="Regular","🔄 Regular",IF(F26="Cursando","📖 Cursando",IF(AND(OR(Datos!A2="Regular",Datos!A2="Aprobada"),OR(Datos!A3="Regular",Datos!A3="Aprobada")),"✅ Disponible","❌ No Disponible")))) -> ❌ No Disponible | I26: =IF(OR(F26="Aprobada",F26="Regular"),"-",IF(H26="✅ Disponible","Sin faltantes",IF(AND(Datos!A2<>"Regular",Datos!A2<>"Aprobada"),A12&"-"&C12&" (cursar); ","")&IF(AND(Datos!A3<>"Regular",Datos!A3<>"Aprobada"),A13&"-"&C13&" (cursar); ",""))) -> 1-Introducción a la Ingeniería Química (cursar); 2-Ingeniería y Sociedad (cursar); | J26: 2
A27: 40 | B27: II | C27: Inglés I | D27: - | E27: - | F27: No Cursada | G27: =IF(Finales!E20="","",Finales!E20) | H27: =IF(F27="Aprobada","✅ Aprobada",IF(F27="Regular","🔄 Regular",IF(F27="Cursando","📖 Cursando","✅ Disponible"))) -> ✅ Disponible | I27: =IF(F27="No Cursada","Sin correlativas","-") -> Sin correlativas | J27: 2
A28: 16 | B28: III | C28: Balances de Masa y Energía | D28: 6, 7, 8, 9, 13 | E28: 1, 3, 4 | F28: No Cursada | G28: =IF(Finales!E21="","",Finales!E21) | H28: =IF(F28="Aprobada","✅ Aprobada",IF(F28="Regular","🔄 Regular",IF(F28="Cursando","📖 Cursando",IF(AND(OR(Datos!A7="Regular",Datos!A7="Aprobada"),OR(Datos!A8="Regular",Datos!A8="Aprobada"),OR(Datos!A9="Regular",Datos!A9="Aprobada"),OR(Datos!A10="Regular",Datos!A10="Aprobada"),OR(Datos!A14="Regular",Datos!A14="Aprobada"),Datos!A2="Aprobada",Datos!A4="Aprobada",Datos!A5="Aprobada"),"✅ Disponible","❌ No Disponible")))) -> ❌ No Disponible | I28: =IF(OR(F28="Aprobada",F28="Regular"),"-",IF(H28="✅ Disponible","Sin faltantes",IF(AND(Datos!A7<>"Regular",Datos!A7<>"Aprobada"),A17&"-"&C17&" (cursar); ","")&IF(AND(Datos!A8<>"Regular",Datos!A8<>"Aprobada"),A18&"-"&C18&" (cursar); ","")&IF(AND(Datos!A9<>"Regular",Datos!A9<>"Aprobada"),A19&"-"&C19&" (cursar); ","")&IF(AND(Datos!A10<>"Regular",Datos!A10<>"Aprobada"),A20&"-"&C20&" (cursar); ","")&IF(AND(Datos!A14<>"Regular",Datos!A14<>"Aprobada"),A24&"-"&C24&" (cursar); ","")&IF(Datos!A2<>"Aprobada",A12&"-"&C12&" (aprobar); ","")&IF(Datos!A4<>"Aprobada",A14&"-"&C14&" (aprobar); ","")&IF(Datos!A5<>"Aprobada",A15&"-"&C15&" (aprobar); ",""))) -> 6-Química (cursar); 7-Sistemas de Representación (cursar); 8-Fundamentos de Informática (cursar); 9-Introducción a Equipos y Procesos (cursar); 13-Física II (cursar); 1-Introducción a la Ingeniería Química (aprobar); 3-Álgebra y Geometría Analítica (aprobar); 4-Análisis Matemático I (aprobar); | J28: 3
A29: 17 | B29: III | C29: Termodinámica | D29: 11, 12, 13 | E29: 4, 6 | F29: No Cursada | G29: =IF(Finales!E22="","",Finales!E22) | H29: =IF(F29="Aprobada","✅ Aprobada",IF(F29="Regular","🔄 Regular",IF(F29="Cursando","📖 Cursando",IF(AND(OR(Datos!A12="Regular",Datos!A12="Aprobada"),OR(Datos!A13="Regular",Datos!A13="Aprobada"),OR(Datos!A14="Regular",Datos!A14="Aprobada"),Datos!A5="Aprobada",Datos!A7="Aprobada"),"✅ Disponible","❌ No Disponible")))) -> ❌ No Disponible | I29: =IF(OR(F29="Aprobada",F29="Regular"),"-",IF(H29="✅ Disponible","Sin faltantes",IF(AND(Datos!A12<>"Regular",Datos!A12<>"Aprobada"),A22&"-"&C22&" (cursar); ","")&IF(AND(Datos!A13<>"Regular",Datos!A13<>"Aprobada"),A23&"-"&C23&" (cursar); ","")&IF(AND(Datos!A14<>"Regular",Datos!A14<>"Aprobada"),A24&"-"&C24&" (cursar); ","")&IF(Datos!A5<>"Aprobada",A15&"-"&C15&" (aprobar); ","")&IF(Datos!A7<>"Aprobada",A17&"-"&C17&" (aprobar); ",""))) -> 11-Química Inorgánica (cursar); 12-Análisis Matemático II (cursar); 13-Física II (cursar); 4-Análisis Matemático I (aprobar); 6-Química (aprobar); | J29: 4
A30: 18 | B30: III | C30: Matemática Superior Aplicada | D30: 12 | E30: 3, 4 | F30: No Cursada | G30: =IF(Finales!E23="","",Finales!E23) | H30: =IF(F30="Aprobada","✅ Aprobada",IF(F30="Regular","🔄 Regular",IF(F30="Cursando","📖 Cursando",IF(AND(OR(Datos!A13="Regular",Datos!A13="Aprobada"),Datos!A4="Aprobada",Datos!A5="Aprobada"),"✅ Disponible","❌ No Disponible")))) -> ❌ No Disponible | I30: =IF(OR(F30="Aprobada",F30="Regular"),"-",IF(H30="✅ Disponible","Sin faltantes",IF(AND(Datos!A13<>"Regular",Datos!A13<>"Aprobada"),A23&"-"&C23&" (cursar); ","")&IF(Datos!A4<>"Aprobada",A14&"-"&C14&" (aprobar); ","")&IF(Datos!A5<>"Aprobada",A15&"-"&C15&" (aprobar); ",""))) -> 12-Análisis Matemático II (cursar); 3-Álgebra y Geometría Analítica (aprobar); 4-Análisis Matemático I (aprobar); | J30: 3
A31: 19 | B31: III | C31: Ciencia de los Materiales | D31: 9, 11, 14 | E31: 1, 6 | F31: No Cursada | G31: =IF(Finales!E24="","",Finales!E24) | H31: =IF(F31="Aprobada","✅ Aprobada",IF(F31="Regular","🔄 Regular",IF(F31="Cursando","📖 Cursando",IF(AND(OR(Datos!A10="Regular",Datos!A10="Aprobada"),OR(Datos!A12="Regular",Datos!A12="Aprobada"),OR(Datos!A15="Regular",Datos!A15="Aprobada"),Datos!A2="Aprobada",Datos!A7="Aprobada"),"✅ Disponible","❌ No Disponible")))) -> ❌ No Disponible | I31: =IF(OR(F31="Aprobada",F31="Regular"),"-",IF(H31="✅ Disponible","Sin faltantes",IF(AND(Datos!A10<>"Regular",Datos!A10<>"Aprobada"),A20&"-"&C20&" (cursar); ","")&IF(AND(Datos!A12<>"Regular",Datos!A12<>"Aprobada"),A22&"-"&C22&" (cursar); ","")&IF(AND(Datos!A15<>"Regular",Datos!A15<>"Aprobada"),A25&"-"&C25&" (cursar); ","")&IF(Datos!A2<>"Aprobada",A12&"-"&C12&" (aprobar); ","")&IF(Datos!A7<>"Aprobada",A17&"-"&C17&" (aprobar); ",""))) -> 9-Introducción a Equipos y Procesos (cursar); 11-Química Inorgánica (cursar); 14-Química Orgánica (cursar); 1-Introducción a la Ingeniería Química (aprobar); 6-Química (aprobar); | J31: 2
A32: 20 | B32: III | C32: Fisicoquímica | D32: 9, 12, 13 | E32: 3, 4, 6 | F32: No Cursada | G32: =IF(Finales!E25="","",Finales!E25) | H32: =IF(F32="Aprobada","✅ Aprobada",IF(F32="Regular","🔄 Regular",IF(F32="Cursando","📖 Cursando",IF(AND(OR(Datos!A10="Regular",Datos!A10="Aprobada"),OR(Datos!A13="Regular",Datos!A13="Aprobada"),OR(Datos!A14="Regular",Datos!A14="Aprobada"),Datos!A4="Aprobada",Datos!A5="Aprobada",Datos!A7="Aprobada"),"✅ Disponible","❌ No Disponible")))) -> ❌ No Disponible | I32: =IF(OR(F32="Aprobada",F32="Regular"),"-",IF(H32="✅ Disponible","Sin faltantes",IF(AND(Datos!A10<>"Regular",Datos!A10<>"Aprobada"),A20&"-"&C20&" (cursar); ","")&IF(AND(Datos!A13<>"Regular",Datos!A13<>"Aprobada"),A23&"-"&C23&" (cursar); ","")&IF(AND(Datos!A14<>"Regular",Datos!A14<>"Aprobada"),A24&"-"&C24&" (cursar); ","")&IF(Datos!A4<>"Aprobada",A14&"-"&C14&" (aprobar); ","")&IF(Datos!A5<>"Aprobada",A15&"-"&C15&" (aprobar); ","")&IF(Datos!A7<>"Aprobada",A17&"-"&C17&" (aprobar); ",""))) -> 9-Introducción a Equipos y Procesos (cursar); 12-Análisis Matemático II (cursar); 13-Física II (cursar); 3-Álgebra y Geometría Analítica (aprobar); 4-Análisis Matemático I (aprobar); 6-Química (aprobar); | J32: 4
A33: 21 | B33: III | C33: Fenómenos de Transporte | D33: 9, 12, 13 | E33: 3, 4, 6 | F33: No Cursada | G33: =IF(Finales!E26="","",Finales!E26) | H33: =IF(F33="Aprobada","✅ Aprobada",IF(F33="Regular","🔄 Regular",IF(F33="Cursando","📖 Cursando",IF(AND(OR(Datos!A10="Regular",Datos!A10="Aprobada"),OR(Datos!A13="Regular",Datos!A13="Aprobada"),OR(Datos!A14="Regular",Datos!A14="Aprobada"),Datos!A4="Aprobada",Datos!A5="Aprobada",Datos!A7="Aprobada"),"✅ Disponible","❌ No Disponible")))) -> ❌ No Disponible | I33: =IF(OR(F33="Aprobada",F33="Regular"),"-",IF(H33="✅ Disponible","Sin faltantes",IF(AND(Datos!A10<>"Regular",Datos!A10<>"Aprobada"),A20&"-"&C20&" (cursar); ","")&IF(AND(Datos!A13<>"Regular",Datos!A13<>"Aprobada"),A23&"-"&C23&" (cursar); ","")&IF(AND(Datos!A14<>"Regular",Datos!A14<>"Aprobada"),A24&"-"&C24&" (cursar); ","")&IF(Datos!A4<>"Aprobada",A14&"-"&C14&" (aprobar); ","")&IF(Datos!A5<>"Aprobada",A15&"-"&C15&" (aprobar); ","")&IF(Datos!A7<>"Aprobada",A17&"-"&C17&" (aprobar); ",""))) -> 9-Introducción a Equipos y Procesos (cursar); 12-Análisis Matemático II (cursar); 13-Física II (cursar); 3-Álgebra y Geometría Analítica (aprobar); 4-Análisis Matemático I (aprobar); 6-Química (aprobar); | J33: 5
A34: 22 | B34: III | C34: Química Analítica | D34: 10, 11, 14 | E34: 2, 6 | F34: No Cursada | G34: =IF(Finales!E27="","",Finales!E27) | H34: =IF(F34="Aprobada","✅ Aprobada",IF(F34="Regular","🔄 Regular",IF(F34="Cursando","📖 Cursando",IF(AND(OR(Datos!A11="Regular",Datos!A11="Aprobada"),OR(Datos!A12="Regular",Datos!A12="Aprobada"),OR(Datos!A15="Regular",Datos!A15="Aprobada"),Datos!A3="Aprobada",Datos!A7="Aprobada"),"✅ Disponible","❌ No Disponible")))) -> ❌ No Disponible | I34: =IF(OR(F34="Aprobada",F34="Regular"),"-",IF(H34="✅ Disponible","Sin faltantes",IF(AND(Datos!A11<>"Regular",Datos!A11<>"Aprobada"),A21&"-"&C21&" (cursar); ","")&IF(AND(Datos!A12<>"Regular",Datos!A12<>"Aprobada"),A22&"-"&C22&" (cursar); ","")&IF(AND(Datos!A15<>"Regular",Datos!A15<>"Aprobada"),A25&"-"&C25&" (cursar); ","")&IF(Datos!A3<>"Aprobada",A13&"-"&C13&" (aprobar); ","")&IF(Datos!A7<>"Aprobada",A17&"-"&C17&" (aprobar); ",""))) -> 10-Probabilidad y Estadística (cursar); 11-Química Inorgánica (cursar); 14-Química Orgánica (cursar); 2-Ingeniería y Sociedad (aprobar); 6-Química (aprobar); | J34: 4
A35: 23 | B35: III | C35: Microbiología y Química Biológica | D35: 11, 14 | E35: 6 | F35: No Cursada | G35: =IF(Finales!E28="","",Finales!E28) | H35: =IF(F35="Aprobada","✅ Aprobada",IF(F35="Regular","🔄 Regular",IF(F35="Cursando","📖 Cursando",IF(AND(OR(Datos!A12="Regular",Datos!A12="Aprobada"),OR(Datos!A15="Regular",Datos!A15="Aprobada"),Datos!A7="Aprobada"),"✅ Disponible","❌ No Disponible")))) -> ❌ No Disponible | I35: =IF(OR(F35="Aprobada",F35="Regular"),"-",IF(H35="✅ Disponible","Sin faltantes",IF(AND(Datos!A12<>"Regular",Datos!A12<>"Aprobada"),A22&"-"&C22&" (cursar); ","")&IF(AND(Datos!A15<>"Regular",Datos!A15<>"Aprobada"),A25&"-"&C25&" (cursar); ","")&IF(Datos!A7<>"Aprobada",A17&"-"&C17&" (aprobar); ",""))) -> 11-Química Inorgánica (cursar); 14-Química Orgánica (cursar); 6-Química (aprobar); | J35: 3
A36: 24 | B36: III | C36: Química Aplicada | D36: 9, 11, 13, 14 | E36: 1, 2, 6, 40 | F36: No Cursada | G36: =IF(Finales!E29="","",Finales!E29) | H36: =IF(F36="Aprobada","✅ Aprobada",IF(F36="Regular","🔄 Regular",IF(F36="Cursando","📖 Cursando",IF(AND(OR(Datos!A10="Regular",Datos!A10="Aprobada"),OR(Datos!A12="Regular",Datos!A12="Aprobada"),OR(Datos!A14="Regular",Datos!A14="Aprobada"),OR(Datos!A15="Regular",Datos!A15="Aprobada"),Datos!A2="Aprobada",Datos!A3="Aprobada",Datos!A7="Aprobada",Datos!A17="Aprobada"),"✅ Disponible","❌ No Disponible")))) -> ❌ No Disponible | I36: =IF(OR(F36="Aprobada",F36="Regular"),"-",IF(H36="✅ Disponible","Sin faltantes",IF(AND(Datos!A10<>"Regular",Datos!A10<>"Aprobada"),A20&"-"&C20&" (cursar); ","")&IF(AND(Datos!A12<>"Regular",Datos!A12<>"Aprobada"),A22&"-"&C22&" (cursar); ","")&IF(AND(Datos!A14<>"Regular",Datos!A14<>"Aprobada"),A24&"-"&C24&" (cursar); ","")&IF(AND(Datos!A15<>"Regular",Datos!A15<>"Aprobada"),A25&"-"&C25&" (cursar); ","")&IF(Datos!A2<>"Aprobada",A12&"-"&C12&" (aprobar); ","")&IF(Datos!A3<>"Aprobada",A13&"-"&C13&" (aprobar); ","")&IF(Datos!A7<>"Aprobada",A17&"-"&C17&" (aprobar); ","")&IF(Datos!A17<>"Aprobada",A27&"-"&C27&" (aprobar); ",""))) -> 9-Introducción a Equipos y Procesos (cursar); 11-Química Inorgánica (cursar); 13-Física II (cursar); 14-Química Orgánica (cursar); 1-Introducción a la Ingeniería Química (aprobar); 2-Ingeniería y Sociedad (aprobar); 6-Química (aprobar); 40-Inglés I (aprobar); | J36: 2
A37: 41 | B37: III | C37: Inglés II | D37: 40 | E37: - | F37: No Cursada | G37: =IF(Finales!E30="","",Finales!E30) | H37: =IF(F37="Aprobada","✅ Aprobada",IF(F37="Regular","🔄 Regular",IF(F37="Cursando","📖 Cursando",IF(AND(OR(Datos!A17="Regular",Datos!A17="Aprobada")),"✅ Disponible","❌ No Disponible")))) -> ❌ No Disponible | I37: =IF(OR(F37="Aprobada",F37="Regular"),"-",IF(H37="✅ Disponible","Sin faltantes",IF(AND(Datos!A17<>"Regular",Datos!A17<>"Aprobada"),A27&"-"&C27&" (cursar); ",""))) -> 40-Inglés I (cursar); | J37: 2
A38: 25 | B38: IV | C38: Diseño, simulación, optimización y seguridad | D38: 16, 18 | E38: 7, 8, 9, 12, 41 | F38: No Cursada | G38: =IF(Finales!E31="","",Finales!E31) | H38: =IF(F38="Aprobada","✅ Aprobada",IF(F38="Regular","🔄 Regular",IF(F38="Cursando","📖 Cursando",IF(AND(OR(Datos!A18="Regular",Datos!A18="Aprobada"),OR(Datos!A20="Regular",Datos!A20="Aprobada"),Datos!A8="Aprobada",Datos!A9="Aprobada",Datos!A10="Aprobada",Datos!A13="Aprobada",Datos!A27="Aprobada"),"✅ Disponible","❌ No Disponible")))) -> ❌ No Disponible | I38: =IF(OR(F38="Aprobada",F38="Regular"),"-",IF(H38="✅ Disponible","Sin faltantes",IF(AND(Datos!A18<>"Regular",Datos!A18<>"Aprobada"),A28&"-"&C28&" (cursar); ","")&IF(AND(Datos!A20<>"Regular",Datos!A20<>"Aprobada"),A30&"-"&C30&" (cursar); ","")&IF(Datos!A8<>"Aprobada",A18&"-"&C18&" (aprobar); ","")&IF(Datos!A9<>"Aprobada",A19&"-"&C19&" (aprobar); ","")&IF(Datos!A10<>"Aprobada",A20&"-"&C20&" (aprobar); ","")&IF(Datos!A13<>"Aprobada",A23&"-"&C23&" (aprobar); ","")&IF(Datos!A27<>"Aprobada",A37&"-"&C37&" (aprobar); ",""))) -> 16-Balances de Masa y Energía (cursar); 18-Matemática Superior Aplicada (cursar); 7-Sistemas de Representación (aprobar); 8-Fundamentos de Informática (aprobar); 9-Introducción a Equipos y Procesos (aprobar); 12-Análisis Matemático II (aprobar); 41-Inglés II (aprobar); | J38: 4
A39: 26 | B39: IV | C39: Operaciones Unitarias I | D39: 16, 17, 21 | E39: 9, 12, 13 | F39: No Cursada | G39: =IF(Finales!E32="","",Finales!E32) | H39: =IF(F39="Aprobada","✅ Aprobada",IF(F39="Regular","🔄 Regular",IF(F39="Cursando","📖 Cursando",IF(AND(OR(Datos!A18="Regular",Datos!A18="Aprobada"),OR(Datos!A19="Regular",Datos!A19="Aprobada"),OR(Datos!A23="Regular",Datos!A23="Aprobada"),Datos!A10="Aprobada",Datos!A13="Aprobada",Datos!A14="Aprobada"),"✅ Disponible","❌ No Disponible")))) -> ❌ No Disponible | I39: =IF(OR(F39="Aprobada",F39="Regular"),"-",IF(H39="✅ Disponible","Sin faltantes",IF(AND(Datos!A18<>"Regular",Datos!A18<>"Aprobada"),A28&"-"&C28&" (cursar); ","")&IF(AND(Datos!A19<>"Regular",Datos!A19<>"Aprobada"),A29&"-"&C29&" (cursar); ","")&IF(AND(Datos!A23<>"Regular",Datos!A23<>"Aprobada"),A33&"-"&C33&" (cursar); ","")&IF(Datos!A10<>"Aprobada",A20&"-"&C20&" (aprobar); ","")&IF(Datos!A13<>"Aprobada",A23&"-"&C23&" (aprobar); ","")&IF(Datos!A14<>"Aprobada",A24&"-"&C24&" (aprobar); ",""))) -> 16-Balances de Masa y Energía (cursar); 17-Termodinámica (cursar); 21-Fenómenos de Transporte (cursar); 9-Introducción a Equipos y Procesos (aprobar); 12-Análisis Matemático II (aprobar); 13-Física II (aprobar); | J39: 5
A40: 27 | B40: IV | C40: Tecnología de la Energía Térmica | D40: 16, 17, 20, 21 | E40: 9, 12, 13 | F40: No Cursada | G40: =IF(Finales!E33="","",Finales!E33) | H40: =IF(F40="Aprobada","✅ Aprobada",IF(F40="Regular","🔄 Regular",IF(F40="Cursando","📖 Cursando",IF(AND(OR(Datos!A18="Regular",Datos!A18="Aprobada"),OR(Datos!A19="Regular",Datos!A19="Aprobada"),OR(Datos!A22="Regular",Datos!A22="Aprobada"),OR(Datos!A23="Regular",Datos!A23="Aprobada"),Datos!A10="Aprobada",Datos!A13="Aprobada",Datos!A14="Aprobada"),"✅ Disponible","❌ No Disponible")))) -> ❌ No Disponible | I40: =IF(OR(F40="Aprobada",F40="Regular"),"-",IF(H40="✅ Disponible","Sin faltantes",IF(AND(Datos!A18<>"Regular",Datos!A18<>"Aprobada"),A28&"-"&C28&" (cursar); ","")&IF(AND(Datos!A19<>"Regular",Datos!A19<>"Aprobada"),A29&"-"&C29&" (cursar); ","")&IF(AND(Datos!A22<>"Regular",Datos!A22<>"Aprobada"),A32&"-"&C32&" (cursar); ","")&IF(AND(Datos!A23<>"Regular",Datos!A23<>"Aprobada"),A33&"-"&C33&" (cursar); ","")&IF(Datos!A10<>"Aprobada",A20&"-"&C20&" (aprobar); ","")&IF(Datos!A13<>"Aprobada",A23&"-"&C23&" (aprobar); ","")&IF(Datos!A14<>"Aprobada",A24&"-"&C24&" (aprobar); ",""))) -> 16-Balances de Masa y Energía (cursar); 17-Termodinámica (cursar); 20-Fisicoquímica (cursar); 21-Fenómenos de Transporte (cursar); 9-Introducción a Equipos y Procesos (aprobar); 12-Análisis Matemático II (aprobar); 13-Física II (aprobar); | J40: 5
A41: 28 | B41: IV | C41: Economía | D41: 9 | E41: 2, 3 | F41: No Cursada | G41: =IF(Finales!E34="","",Finales!E34) | H41: =IF(F41="Aprobada","✅ Aprobada",IF(F41="Regular","🔄 Regular",IF(F41="Cursando","📖 Cursando",IF(AND(OR(Datos!A10="Regular",Datos!A10="Aprobada"),Datos!A3="Aprobada",Datos!A4="Aprobada"),"✅ Disponible","❌ No Disponible")))) -> ❌ No Disponible | I41: =IF(OR(F41="Aprobada",F41="Regular"),"-",IF(H41="✅ Disponible","Sin faltantes",IF(AND(Datos!A10<>"Regular",Datos!A10<>"Aprobada"),A20&"-"&C20&" (cursar); ","")&IF(Datos!A3<>"Aprobada",A13&"-"&C13&" (aprobar); ","")&IF(Datos!A4<>"Aprobada",A14&"-"&C14&" (aprobar); ",""))) -> 9-Introducción a Equipos y Procesos (cursar); 2-Ingeniería y Sociedad (aprobar); 3-Álgebra y Geometría Analítica (aprobar); | J41: 3
A42: 29 | B42: IV | C42: Operaciones Unitarias II | D42: 17, 20, 21 | E42: 9, 12, 13, 14 | F42: No Cursada | G42: =IF(Finales!E35="","",Finales!E35) | H42: =IF(F42="Aprobada","✅ Aprobada",IF(F42="Regular","🔄 Regular",IF(F42="Cursando","📖 Cursando",IF(AND(OR(Datos!A19="Regular",Datos!A19="Aprobada"),OR(Datos!A22="Regular",Datos!A22="Aprobada"),OR(Datos!A23="Regular",Datos!A23="Aprobada"),Datos!A10="Aprobada",Datos!A13="Aprobada",Datos!A14="Aprobada",Datos!A15="Aprobada"),"✅ Disponible","❌ No Disponible")))) -> ❌ No Disponible | I42: =IF(OR(F42="Aprobada",F42="Regular"),"-",IF(H42="✅ Disponible","Sin faltantes",IF(AND(Datos!A19<>"Regular",Datos!A19<>"Aprobada"),A29&"-"&C29&" (cursar); ","")&IF(AND(Datos!A22<>"Regular",Datos!A22<>"Aprobada"),A32&"-"&C32&" (cursar); ","")&IF(AND(Datos!A23<>"Regular",Datos!A23<>"Aprobada"),A33&"-"&C33&" (cursar); ","")&IF(Datos!A10<>"Aprobada",A20&"-"&C20&" (aprobar); ","")&IF(Datos!A13<>"Aprobada",A23&"-"&C23&" (aprobar); ","")&IF(Datos!A14<>"Aprobada",A24&"-"&C24&" (aprobar); ","")&IF(Datos!A15<>"Aprobada",A25&"-"&C25&" (aprobar); ",""))) -> 17-Termodinámica (cursar); 20-Fisicoquímica (cursar); 21-Fenómenos de Transporte (cursar); 9-Introducción a Equipos y Procesos (aprobar); 12-Análisis Matemático II (aprobar); 13-Física II (aprobar); 14-Química Orgánica (aprobar); | J42: 5
A43: 30 | B43: IV | C43: Ingeniería de las Reacciones Químicas | D43: 16, 17, 20, 21 | E43: 11, 12, 14 | F43: No Cursada | G43: =IF(Finales!E36="","",Finales!E36) | H43: =IF(F43="Aprobada","✅ Aprobada",IF(F43="Regular","🔄 Regular",IF(F43="Cursando","📖 Cursando",IF(AND(OR(Datos!A18="Regular",Datos!A18="Aprobada"),OR(Datos!A19="Regular",Datos!A19="Aprobada"),OR(Datos!A22="Regular",Datos!A22="Aprobada"),OR(Datos!A23="Regular",Datos!A23="Aprobada"),Datos!A12="Aprobada",Datos!A13="Aprobada",Datos!A15="Aprobada"),"✅ Disponible","❌ No Disponible")))) -> ❌ No Disponible | I43: =IF(OR(F43="Aprobada",F43="Regular"),"-",IF(H43="✅ Disponible","Sin faltantes",IF(AND(Datos!A18<>"Regular",Datos!A18<>"Aprobada"),A28&"-"&C28&" (cursar); ","")&IF(AND(Datos!A19<>"Regular",Datos!A19<>"Aprobada"),A29&"-"&C29&" (cursar); ","")&IF(AND(Datos!A22<>"Regular",Datos!A22<>"Aprobada"),A32&"-"&C32&" (cursar); ","")&IF(AND(Datos!A23<>"Regular",Datos!A23<>"Aprobada"),A33&"-"&C33&" (cursar); ","")&IF(Datos!A12<>"Aprobada",A22&"-"&C22&" (aprobar); ","")&IF(Datos!A13<>"Aprobada",A23&"-"&C23&" (aprobar); ","")&IF(Datos!A15<>"Aprobada",A25&"-"&C25&" (aprobar); ",""))) -> 16-Balances de Masa y Energía (cursar); 17-Termodinámica (cursar); 20-Fisicoquímica (cursar); 21-Fenómenos de Transporte (cursar); 11-Química Inorgánica (aprobar); 12-Análisis Matemático II (aprobar); 14-Química Orgánica (aprobar); | J43: 5
...

Sheet Finales
A1: 📝 REGISTRO DE EXÁMENES FINALES
A2: Ingrese las notas de cada intento de final. Se aprueba con 6. Máximo 4 instancias por materia en condición regular.
A4: N° | B4: NIVEL | C4: ASIGNATURA | D4: ESTADO | E4: NOTA FINAL | F4: FECHA 1° | G4: 1° NOTA | H4: FECHA 2° | I4: 2° NOTA | J4: FECHA 3° | K4: 3° NOTA | L4: FECHA 4° | M4: 4° NOTA | N4: FECHA 5° | O4: 5° NOTA | P4: FECHA 6° | Q4: 6° NOTA
A5: 1 | B5: I | C5: Introducción a la Ingeniería Química | D5: =Seguimiento!F12 -> No Cursada | E5: =IF(COUNTA(G5,I5,K5,M5,O5,Q5)=0,"",IF(MAX(IF(G5>=6,G5,0),IF(I5>=6,I5,0),IF(K5>=6,K5,0),IF(M5>=6,M5,0),IF(O5>=6,O5,0),IF(Q5>=6,Q5,0))>0,MAX(IF(G5>=6,G5,0),IF(I5>=6,I5,0),IF(K5>=6,K5,0),IF(M5>=6,M5,0),IF(O5>=6,O5,0),IF(Q5>=6,Q5,0)),IF(Q5<>"",Q5,IF(O5<>"",O5,IF(M5<>"",M5,IF(K5<>"",K5,IF(I5<>"",I5,G5)))))))
A6: 2 | B6: I | C6: Ingeniería y Sociedad | D6: =Seguimiento!F13 -> No Cursada | E6: =IF(COUNTA(G6,I6,K6,M6,O6,Q6)=0,"",IF(MAX(IF(G6>=6,G6,0),IF(I6>=6,I6,0),IF(K6>=6,K6,0),IF(M6>=6,M6,0),IF(O6>=6,O6,0),IF(Q6>=6,Q6,0))>0,MAX(IF(G6>=6,G6,0),IF(I6>=6,I6,0),IF(K6>=6,K6,0),IF(M6>=6,M6,0),IF(O6>=6,O6,0),IF(Q6>=6,Q6,0)),IF(Q6<>"",Q6,IF(O6<>"",O6,IF(M6<>"",M6,IF(K6<>"",K6,IF(I6<>"",I6,G6)))))))
A7: 3 | B7: I | C7: Álgebra y Geometría Analítica | D7: =Seguimiento!F14 -> No Cursada | E7: =IF(COUNTA(G7,I7,K7,M7,O7,Q7)=0,"",IF(MAX(IF(G7>=6,G7,0),IF(I7>=6,I7,0),IF(K7>=6,K7,0),IF(M7>=6,M7,0),IF(O7>=6,O7,0),IF(Q7>=6,Q7,0))>0,MAX(IF(G7>=6,G7,0),IF(I7>=6,I7,0),IF(K7>=6,K7,0),IF(M7>=6,M7,0),IF(O7>=6,O7,0),IF(Q7>=6,Q7,0)),IF(Q7<>"",Q7,IF(O7<>"",O7,IF(M7<>"",M7,IF(K7<>"",K7,IF(I7<>"",I7,G7)))))))
A8: 4 | B8: I | C8: Análisis Matemático I | D8: =Seguimiento!F15 -> No Cursada | E8: =IF(COUNTA(G8,I8,K8,M8,O8,Q8)=0,"",IF(MAX(IF(G8>=6,G8,0),IF(I8>=6,I8,0),IF(K8>=6,K8,0),IF(M8>=6,M8,0),IF(O8>=6,O8,0),IF(Q8>=6,Q8,0))>0,MAX(IF(G8>=6,G8,0),IF(I8>=6,I8,0),IF(K8>=6,K8,0),IF(M8>=6,M8,0),IF(O8>=6,O8,0),IF(Q8>=6,Q8,0)),IF(Q8<>"",Q8,IF(O8<>"",O8,IF(M8<>"",M8,IF(K8<>"",K8,IF(I8<>"",I8,G8)))))))
A9: 5 | B9: I | C9: Física I | D9: =Seguimiento!F16 -> No Cursada | E9: =IF(COUNTA(G9,I9,K9,M9,O9,Q9)=0,"",IF(MAX(IF(G9>=6,G9,0),IF(I9>=6,I9,0),IF(K9>=6,K9,0),IF(M9>=6,M9,0),IF(O9>=6,O9,0),IF(Q9>=6,Q9,0))>0,MAX(IF(G9>=6,G9,0),IF(I9>=6,I9,0),IF(K9>=6,K9,0),IF(M9>=6,M9,0),IF(O9>=6,O9,0),IF(Q9>=6,Q9,0)),IF(Q9<>"",Q9,IF(O9<>"",O9,IF(M9<>"",M9,IF(K9<>"",K9,IF(I9<>"",I9,G9)))))))
A10: 6 | B10: I | C10: Química | D10: =Seguimiento!F17 -> No Cursada | E10: =IF(COUNTA(G10,I10,K10,M10,O10,Q10)=0,"",IF(MAX(IF(G10>=6,G10,0),IF(I10>=6,I10,0),IF(K10>=6,K10,0),IF(M10>=6,M10,0),IF(O10>=6,O10,0),IF(Q10>=6,Q10,0))>0,MAX(IF(G10>=6,G10,0),IF(I10>=6,I10,0),IF(K10>=6,K10,0),IF(M10>=6,M10,0),IF(O10>=6,O10,0),IF(Q10>=6,Q10,0)),IF(Q10<>"",Q10,IF(O10<>"",O10,IF(M10<>"",M10,IF(K10<>"",K10,IF(I10<>"",I10,G10)))))))
A11: 7 | B11: I | C11: Sistemas de Representación | D11: =Seguimiento!F18 -> No Cursada | E11: =IF(COUNTA(G11,I11,K11,M11,O11,Q11)=0,"",IF(MAX(IF(G11>=6,G11,0),IF(I11>=6,I11,0),IF(K11>=6,K11,0),IF(M11>=6,M11,0),IF(O11>=6,O11,0),IF(Q11>=6,Q11,0))>0,MAX(IF(G11>=6,G11,0),IF(I11>=6,I11,0),IF(K11>=6,K11,0),IF(M11>=6,M11,0),IF(O11>=6,O11,0),IF(Q11>=6,Q11,0)),IF(Q11<>"",Q11,IF(O11<>"",O11,IF(M11<>"",M11,IF(K11<>"",K11,IF(I11<>"",I11,G11)))))))
A12: 8 | B12: I | C12: Fundamentos de Informática | D12: =Seguimiento!F19 -> No Cursada | E12: =IF(COUNTA(G12,I12,K12,M12,O12,Q12)=0,"",IF(MAX(IF(G12>=6,G12,0),IF(I12>=6,I12,0),IF(K12>=6,K12,0),IF(M12>=6,M12,0),IF(O12>=6,O12,0),IF(Q12>=6,Q12,0))>0,MAX(IF(G12>=6,G12,0),IF(I12>=6,I12,0),IF(K12>=6,K12,0),IF(M12>=6,M12,0),IF(O12>=6,O12,0),IF(Q12>=6,Q12,0)),IF(Q12<>"",Q12,IF(O12<>"",O12,IF(M12<>"",M12,IF(K12<>"",K12,IF(I12<>"",I12,G12)))))))
A13: 9 | B13: II | C13: Introducción a Equipos y Procesos | D13: =Seguimiento!F20 -> No Cursada | E13: =IF(COUNTA(G13,I13,K13,M13,O13,Q13)=0,"",IF(MAX(IF(G13>=6,G13,0),IF(I13>=6,I13,0),IF(K13>=6,K13,0),IF(M13>=6,M13,0),IF(O13>=6,O13,0),IF(Q13>=6,Q13,0))>0,MAX(IF(G13>=6,G13,0),IF(I13>=6,I13,0),IF(K13>=6,K13,0),IF(M13>=6,M13,0),IF(O13>=6,O13,0),IF(Q13>=6,Q13,0)),IF(Q13<>"",Q13,IF(O13<>"",O13,IF(M13<>"",M13,IF(K13<>"",K13,IF(I13<>"",I13,G13)))))))
A14: 10 | B14: II | C14: Probabilidad y Estadística | D14: =Seguimiento!F21 -> No Cursada | E14: =IF(COUNTA(G14,I14,K14,M14,O14,Q14)=0,"",IF(MAX(IF(G14>=6,G14,0),IF(I14>=6,I14,0),IF(K14>=6,K14,0),IF(M14>=6,M14,0),IF(O14>=6,O14,0),IF(Q14>=6,Q14,0))>0,MAX(IF(G14>=6,G14,0),IF(I14>=6,I14,0),IF(K14>=6,K14,0),IF(M14>=6,M14,0),IF(O14>=6,O14,0),IF(Q14>=6,Q14,0)),IF(Q14<>"",Q14,IF(O14<>"",O14,IF(M14<>"",M14,IF(K14<>"",K14,IF(I14<>"",I14,G14)))))))
A15: 11 | B15: II | C15: Química Inorgánica | D15: =Seguimiento!F22 -> No Cursada | E15: =IF(COUNTA(G15,I15,K15,M15,O15,Q15)=0,"",IF(MAX(IF(G15>=6,G15,0),IF(I15>=6,I15,0),IF(K15>=6,K15,0),IF(M15>=6,M15,0),IF(O15>=6,O15,0),IF(Q15>=6,Q15,0))>0,MAX(IF(G15>=6,G15,0),IF(I15>=6,I15,0),IF(K15>=6,K15,0),IF(M15>=6,M15,0),IF(O15>=6,O15,0),IF(Q15>=6,Q15,0)),IF(Q15<>"",Q15,IF(O15<>"",O15,IF(M15<>"",M15,IF(K15<>"",K15,IF(I15<>"",I15,G15)))))))
A16: 12 | B16: II | C16: Análisis Matemático II | D16: =Seguimiento!F23 -> No Cursada | E16: =IF(COUNTA(G16,I16,K16,M16,O16,Q16)=0,"",IF(MAX(IF(G16>=6,G16,0),IF(I16>=6,I16,0),IF(K16>=6,K16,0),IF(M16>=6,M16,0),IF(O16>=6,O16,0),IF(Q16>=6,Q16,0))>0,MAX(IF(G16>=6,G16,0),IF(I16>=6,I16,0),IF(K16>=6,K16,0),IF(M16>=6,M16,0),IF(O16>=6,O16,0),IF(Q16>=6,Q16,0)),IF(Q16<>"",Q16,IF(O16<>"",O16,IF(M16<>"",M16,IF(K16<>"",K16,IF(I16<>"",I16,G16)))))))
... A58: 54 | B58: X | C58: Estudios y Análisis de Procesos de Trabajo (Elect.) | D58: =Seguimiento!F65 -> No Cursada | E58: =IF(COUNTA(G58,I58,K58,M58,O58,Q58)=0,"",IF(MAX(IF(G58>=6,G58,0),IF(I58>=6,I58,0),IF(K58>=6,K58,0),IF(M58>=6,M58,0),IF(O58>=6,O58,0),IF(Q58>=6,Q58,0))>0,MAX(IF(G58>=6,G58,0),IF(I58>=6,I58,0),IF(K58>=6,K58,0),IF(M58>=6,M58,0),IF(O58>=6,O58,0),IF(Q58>=6,Q58,0)),IF(Q58<>"",Q58,IF(O58<>"",O58,IF(M58<>"",M58,IF(K58<>"",K58,IF(I58<>"",I58,G58)))))))

Sheet Nota al Estudiante
E1: 📝 NOTA AL ESTUDIANTE
E2: Seguimiento de Carrera — Ingeniería Química • UTN FRRe

Sheet Datos
A1: Estado Efectivo | C1: Asignatura | D1: Cursadas Requeridas | E1: Aprobadas Requeridas | F1: Fila Seguimiento
A2: =Seguimiento!F12 -> No Cursada | C2: Introducción a la Ingeniería Química | D2: - | E2: - | F2: 12
A3: =Seguimiento!F13 -> No Cursada | C3: Ingeniería y Sociedad | D3: - | E3: - | F3: 13
A4: =Seguimiento!F14 -> No Cursada | C4: Álgebra y Geometría Analítica | D4: - | E4: - | F4: 14
A5: =Seguimiento!F15 -> No Cursada | C5: Análisis Matemático I | D5: - | E5: - | F5: 15
A6: =Seguimiento!F16 -> No Cursada | C6: Física I | D6: - | E6: - | F6: 16
A7: =Seguimiento!F17 -> No Cursada | C7: Química | D7: - | E7: - | F7: 17
A8: =Seguimiento!F18 -> No Cursada | C8: Sistemas de Representación | D8: - | E8: - | F8: 18
A9: =Seguimiento!F19 -> No Cursada | C9: Fundamentos de Informática | D9: - | E9: - | F9: 19
A10: =Seguimiento!F20 -> No Cursada | C10: Introducción a Equipos y Procesos | D10: 1,6 | E10: - | F10: 20
A11: =Seguimiento!F21 -> No Cursada | C11: Probabilidad y Estadística | D11: 3,4 | E11: - | F11: 21
A12: =Seguimiento!F22 -> No Cursada | C12: Química Inorgánica | D12: 6 | E12: - | F12: 22
A13: =Seguimiento!F23 -> No Cursada | C13: Análisis Matemático II | D13: 3,4 | E13: - | F13: 23
A14: =Seguimiento!F24 -> No Cursada | C14: Física II | D14: 4,5 | E14: - | F14: 24
A15: =Seguimiento!F25 -> No Cursada | C15: Química Orgánica | D15: 6 | E15: - | F15: 25
A16: =Seguimiento!F26 -> No Cursada | C16: Legislación | D16: 1,2 | E16: - | F16: 26
A17: =Seguimiento!F27 -> No Cursada | C17: Inglés I | D17: - | E17: - | F17: 27
A18: =Seguimiento!F28 -> No Cursada | C18: Balances de Masa y Energía | D18: 6,7,8,9,13 | E18: 1,3,4 | F18: 28
A19: =Seguimiento!F29 -> No Cursada | C19: Termodinámica | D19: 11,12,13 | E19: 4,6 | F19: 29
A20: =Seguimiento!F30 -> No Cursada | C20: Matemática Superior Aplicada | D20: 12 | E20: 3,4 | F20: 30
A21: =Seguimiento!F31 -> No Cursada | C21: Ciencia de los Materiales | D21: 9,11,14 | E21: 1,6 | F21: 31
A22: =Seguimiento!F32 -> No Cursada | C22: Fisicoquímica | D22: 9,12,13 | E22: 3,4,6 | F22: 32
A23: =Seguimiento!F33 -> No Cursada | C23: Fenómenos de Transporte | D23: 9,12,13 | E23: 3,4,6 | F23: 33
A24: =Seguimiento!F34 -> No Cursada | C24: Química Analítica | D24: 10,11,14 | E24: 2,6 | F24: 34
A25: =Seguimiento!F35 -> No Cursada | C25: Microbiología y Química Biológica | D25: 11,14 | E25: 6 | F25: 35
A26: =Seguimiento!F36 -> No Cursada | C26: Química Aplicada | D26: 9,11,13,14 | E26: 1,2,6,40 | F26: 36
A27: =Seguimiento!F37 -> No Cursada | C27: Inglés II | D27: 40 | E27: - | F27: 37
A28: =Seguimiento!F38 -> No Cursada | C28: Diseño, simulación, optimización y seguridad | D28: 16,18 | E28: 7,8,9,12,41 | F28: 38
A29: =Seguimiento!F39 -> No Cursada | C29: Operaciones Unitarias I | D29: 16,17,21 | E29: 9,12,13 | F29: 39
A30: =Seguimiento!F40 -> No Cursada | C30: Tecnología de la Energía Térmica | D30: 16,17,20,21 | E30: 9,12,13 | F30: 40
A31: =Seguimiento!F41 -> No Cursada | C31: Economía | D31: 9 | E31: 2,3 | F31: 41
A32: =Seguimiento!F42 -> No Cursada | C32: Operaciones Unitarias II | D32: 17,20,21 | E32: 9,12,13,14 | F32: 42
A33: =Seguimiento!F43 -> No Cursada | C33: Ingeniería de las Reacciones Químicas | D33: 16,17,20,21 | E33: 11,12,14 | F33: 43
A34: =Seguimiento!F44 -> No Cursada | C34: Calidad y Control Estadístico de Procesos | D34: 10 | E34: 4 | F34: 44
A35: =Seguimiento!F45 -> No Cursada | C35: Organización Industrial | D35: 10 | E35: 2,9,15 | F35: 45
A36: =Seguimiento!F46 -> No Cursada | C36: Control Automático de Procesos | D36: 25,29 | E36: 16,18,22 | F36: 46
A37: =Seguimiento!F47 -> No Cursada | C37: Mecánica Industrial | D37: 9,20 | E37: 5,11,19 | F37: 47
A38: =Seguimiento!F48 -> No Cursada | C38: Ingeniería Ambiental | D38: 24,26,29,30 | E38: 15,16,22 | F38: 48
A39: =Seguimiento!F49 -> No Cursada | C39: Procesos Biotecnológicos | D39: 16,20,21,23 | E39: 9,11,14 | F39: 49
A40: =Seguimiento!F50 -> No Cursada | C40: Higiene y Seguridad en el Trabajo | D40: 11,14,16 | E40: 9 | F40: 50
...
